[2024-06-11T05:08:57.346+0000] {taskinstance.py:1165} INFO - Dependencies all met for <TaskInstance: example_callback.task3 manual__2024-06-11T05:08:55.138755+00:00 [queued]>
[2024-06-11T05:08:57.350+0000] {taskinstance.py:1165} INFO - Dependencies all met for <TaskInstance: example_callback.task3 manual__2024-06-11T05:08:55.138755+00:00 [queued]>
[2024-06-11T05:08:57.350+0000] {taskinstance.py:1362} INFO - 
--------------------------------------------------------------------------------
[2024-06-11T05:08:57.350+0000] {taskinstance.py:1363} INFO - Starting attempt 1 of 1
[2024-06-11T05:08:57.350+0000] {taskinstance.py:1364} INFO - 
--------------------------------------------------------------------------------
[2024-06-11T05:08:57.356+0000] {taskinstance.py:1383} INFO - Executing <Task(EmptyOperator): task3> on 2024-06-11 05:08:55.138755+00:00
[2024-06-11T05:08:57.359+0000] {standard_task_runner.py:55} INFO - Started process 2254 to run task
[2024-06-11T05:08:57.361+0000] {standard_task_runner.py:82} INFO - Running: ['***', 'tasks', 'run', 'example_callback', 'task3', 'manual__2024-06-11T05:08:55.138755+00:00', '--job-id', '122', '--raw', '--subdir', 'DAGS_FOLDER/callback_example.py', '--cfg-path', '/tmp/tmpli7xniiu']
[2024-06-11T05:08:57.361+0000] {standard_task_runner.py:83} INFO - Job 122: Subtask task3
[2024-06-11T05:08:57.388+0000] {task_command.py:376} INFO - Running <TaskInstance: example_callback.task3 manual__2024-06-11T05:08:55.138755+00:00 [running]> on host 8a665be84819
[2024-06-11T05:08:57.417+0000] {taskinstance.py:1592} INFO - Exporting the following env vars:
AIRFLOW_CTX_DAG_OWNER=***
AIRFLOW_CTX_DAG_ID=example_callback
AIRFLOW_CTX_TASK_ID=task3
AIRFLOW_CTX_EXECUTION_DATE=2024-06-11T05:08:55.138755+00:00
AIRFLOW_CTX_TRY_NUMBER=1
AIRFLOW_CTX_DAG_RUN_ID=manual__2024-06-11T05:08:55.138755+00:00
[2024-06-11T05:08:57.420+0000] {taskinstance.py:1406} INFO - Marking task as SUCCESS. dag_id=example_callback, task_id=task3, execution_date=20240611T050855, start_date=20240611T050857, end_date=20240611T050857
[2024-06-11T05:08:57.421+0000] {taskinstance.py:1619} ERROR - Error when executing on_success callback
Traceback (most recent call last):
  File "/home/airflow/.local/lib/python3.7/site-packages/airflow/models/taskinstance.py", line 1617, in _run_finished_callback
    callback(context)
TypeError: 'list' object is not callable
[2024-06-11T05:08:57.452+0000] {local_task_job.py:164} INFO - Task exited with return code 0
[2024-06-11T05:08:57.461+0000] {local_task_job.py:273} INFO - 0 downstream tasks scheduled from follow-on schedule check
